Workbook
Name \p: #N/A
Name \s: #N/A
Name _____reg12: '[3]Maturity Rpt'!$L$134:$P$135
Name ____L21: '[4]Laser Lease Expense'!$A$2
Name ___CPP1: #REF!
Name ___CPP1: #REF!
Name ___CPP10: #REF!
Name ___CPP10: #REF!
Name ___CPP11: #REF!
Name ___CPP11: #REF!
Name ___CPP12: #REF!
Name ___CPP12: #REF!
Name ___CPP13: #REF!
Name ___CPP13: #REF!
Name ___CPP14: #REF!
Name ___CPP14: #REF!
Name ___CPP15: #REF!
Name ___CPP15: #REF!
Name ___CPP16: #REF!
Name ___CPP16: #REF!
Name ___CPP17: #REF!
Name ___CPP17: #REF!
Name ___CPP18: #REF!
Name ___CPP18: #REF!
Name ___CPP2: #REF!
Name ___CPP2: #REF!
Name ___CPP3: #REF!
Name ___CPP3: #REF!
Name ___CPP4: #REF!
Name ___CPP4: #REF!
Name ___CPP5: #REF!
Name ___CPP5: #REF!
Name ___CPP6: #REF!
Name ___CPP6: #REF!
Name ___CPP7: #REF!
Name ___CPP7: #REF!
Name ___CPP8: #REF!
Name ___CPP8: #REF!
Name ___CPP9: #REF!
Name ___CPP9: #REF!
Name ___L21: '[4]Laser Lease Expense'!$A$2
Name ___MOB1: #REF!
Name ___MOB1: #REF!
Name ___MOB2: #REF!
Name ___MOB2: #REF!
Name ___MOB3: #REF!
Name ___MOB3: #REF!
Name ___MOB4: #REF!
Name ___MOB4: #REF!
Name ___MOB5: #REF!
Name ___MOB5: #REF!
Name ___MOB6: #REF!
Name ___MOB6: #REF!
Name ___MOB7: #REF!
Name ___MOB7: #REF!
Name ___MOB8: #REF!
Name ___MOB8: #REF!
Name ___MOB9: #REF!
Name ___MOB9: #REF!
Name ___PP1: #REF!

Sheet OS Report
B1: 2726 | C1: 000 | E1: OS | F1: Check to TB | H1: BFC | I1: Check to TB | K1: Difference
A2: 4100000 - Revenue | B2: 200353943 | C2: =-B2/1000 -> -200353.94 | E2: =SUMIFS('OS TB'!U:U,'OS TB'!V:V,LEFT(A2,3))/1000 -> -200353.94 | F2: =E2-C2 -> 0 | H2: =-SUMIFS('SAP BFC REPORT'!H:H,'SAP BFC REPORT'!J:J,A2) -> -200353 | I2: =H2-C2 -> 0.943 | K2: =H2-E2 -> 0.943
A3: EXP_EXC_DNA - Operating Expense (Ex-D And A) | B3: -174068474 | C3: =-B3/1000 -> 174068.47
A4: 5010000 - Cost Of Raw Materials And Supplies | B4: -2651110 | C4: =-B4/1000 -> 2651.11 | E4: =SUMIFS('OS TB'!U:U,'OS TB'!V:V,LEFT(A4,3))/1000 -> 2651.11 | F4: =E4-C4 -> 0 | H4: =-SUMIFS('SAP BFC REPORT'!H:H,'SAP BFC REPORT'!J:J,A4) -> 2651 | I4: =H4-C4 -> -0.11 | K4: =H4-E4 -> -0.11
A5: 5020000 - Staff Costs | B5: -126728921 | C5: =-B5/1000 -> 126728.92 | E5: =SUMIFS('OS TB'!U:U,'OS TB'!V:V,LEFT(A5,3))/1000 -> 126728.92 | F5: =E5-C5 -> 0 | H5: =-SUMIFS('SAP BFC REPORT'!H:H,'SAP BFC REPORT'!J:J,A5) -> 126729 | I5: =H5-C5 -> 0.079 | K5: =H5-E5 -> 0.079
A6: 5030000 - Licence Fees | C6: =-B6/1000 -> 0 | E6: =SUMIFS('OS TB'!U:U,'OS TB'!V:V,LEFT(A6,3))/1000 -> 0 | F6: =E6-C6 -> 0 | H6: =-SUMIFS('SAP BFC REPORT'!H:H,'SAP BFC REPORT'!J:J,A6) -> 0 | I6: =H6-C6 -> 0 | K6: =H6-E6 -> 0
A7: 5050000 - Company Premise Utilities And Maintenance | B7: -19704934 | C7: =-B7/1000 -> 19704.934 | E7: =SUMIFS('OS TB'!U:U,'OS TB'!V:V,LEFT(A7,3))/1000 -> 19704.934 | F7: =E7-C7 -> 0 | H7: =-SUMIFS('SAP BFC REPORT'!H:H,'SAP BFC REPORT'!J:J,A7) -> 19674 | I7: =H7-C7 -> -30.934 | K7: =H7-E7 -> -30.934
A8: 5060000 - Subcontracting services | B8: -4712961 | C8: =-B8/1000 -> 4712.961 | E8: =SUMIFS('OS TB'!U:U,'OS TB'!V:V,LEFT(A8,3))/1000 -> 4712.961 | F8: =E8-C8 -> 0 | H8: =-SUMIFS('SAP BFC REPORT'!H:H,'SAP BFC REPORT'!J:J,A8) -> 4713 | I8: =H8-C8 -> 0.039 | K8: =H8-E8 -> 0.039
A9: 5080000 - Other costs | B9: -20270548 | C9: =-B9/1000 -> 20270.548 | E9: =SUMIFS('OS TB'!U:U,'OS TB'!V:V,LEFT(A9,3))/1000 -> 20270.548 | F9: =E9-C9 -> 0 | H9: =-SUMIFS('SAP BFC REPORT'!H:H,'SAP BFC REPORT'!J:J,A9) -> 20302 | I9: =H9-C9 -> 31.452 | K9: =H9-E9 -> 31.452
A10: Trade_Plug - Interco trade (interco revenue and OPEX) plug | C10: =-B10/1000 -> 0 | F10: =E10-C10 -> 0 | I10: =H10-C10 -> 0
A11: EBITDA | B11: 26285469 | C11: =-B11/1000 -> -26285.469
A12: 5040000 - Depreciation And Amortisation | B12: -6558574 | C12: =-B12/1000 -> 6558.574 | E12: =SUMIFS('OS TB'!U:U,'OS TB'!V:V,LEFT(A12,3))/1000 -> 6558.574 | F12: =E12-C12 -> 0 | H12: =-SUMIFS('SAP BFC REPORT'!H:H,'SAP BFC REPORT'!J:J,A12) -> 6558 | I12: =H12-C12 -> -0.574 | K12: =H12-E12 -> -0.574
A13: EBIT | B13: 19726895 | C13: =-B13/1000 -> -19726.895
A14: 6021000 - Finance Income | B14: 7927600 | C14: =-B14/1000 -> -7927.6 | E14: =SUMIFS('OS TB'!U:U,'OS TB'!V:V,LEFT(A14,3))/1000 -> -7927.6 | F14: =E14-C14 -> 0 | H14: =-SUMIFS('SAP BFC REPORT'!H:H,'SAP BFC REPORT'!J:J,A14) -> -7928 | I14: =H14-C14 -> -0.4 | K14: =H14-E14 -> -0.4
A15: 6031000 - Finance Expense | B15: -11672607 | C15: =-B15/1000 -> 11672.607 | E15: =SUMIFS('OS TB'!U:U,'OS TB'!V:V,LEFT(A15,3))/1000 -> 11672.607 | F15: =E15-C15 -> 0 | H15: =-SUMIFS('SAP BFC REPORT'!H:H,'SAP BFC REPORT'!J:J,A15) -> 11672 | I15: =H15-C15 -> -0.607 | K15: =H15-E15 -> -0.607
A16: Interest_Plug_PL - Interco Interest Receivables And Payables Plug | C16: =-B16/1000 -> 0 | F16: =E16-C16 -> 0 | H16: =-SUMIFS('SAP BFC REPORT'!H:H,'SAP BFC REPORT'!J:J,A16) -> 0 | I16: =H16-C16 -> 0
A17: 8010000 - Share Of Results Of AJV | C17: =-B17/1000 -> 0 | F17: =E17-C17 -> 0 | H17: =-SUMIFS('SAP BFC REPORT'!H:H,'SAP BFC REPORT'!J:J,A17) -> 0 | I17: =H17-C17 -> 0
A18: 6010000 - Non operating gain loss | B18: -309157 | C18: =-B18/1000 -> 309.157 | E18: =SUMIFS('OS TB'!U:U,'OS TB'!V:V,LEFT(A18,3))/1000 -> 309.157 | F18: =E18-C18 -> 0 | H18: =-SUMIFS('SAP BFC REPORT'!H:H,'SAP BFC REPORT'!J:J,A18) -> 309 | I18: =H18-C18 -> -0.157 | K18: =H18-E18 -> -0.157
A19: 6990000 - Exceptional Items | C19: =-B19/1000 -> 0 | F19: =E19-C19 -> 0 | H19: =-SUMIFS('SAP BFC REPORT'!H:H,'SAP BFC REPORT'!J:J,A19) -> 0 | I19: =H19-C19 -> 0
A20: PBT - Profit Or Loss Before Tax | B20: 15672731 | C20: =-B20/1000 -> -15672.731
A21: 6070000 - Income Tax Expense | B21: -3448001 | C21: =-B21/1000 -> 3448.001 | E21: =SUMIFS('OS TB'!U:U,'OS TB'!V:V,LEFT(A21,3))/1000 -> 3448.001 | F21: =E21-C21 -> 0 | H21: =-SUMIFS('SAP BFC REPORT'!H:H,'SAP BFC REPORT'!J:J,A21) -> 3448 | I21: =H21-C21 -> -0.001 | K21: =H21-E21 -> -0.001
A22: 8610000 - Profit Or Loss From Discontinued Operation (Net Of Tax) | C22: =-B22/1000 -> 0 | F22: =E22-C22 -> 0 | I22: =H22-C22 -> 0
A23: PAT - Net Profit Or Loss (PAT) | B23: 12224730 | C23: =-B23/1000 -> -12224.73
A24: PL_MI - Minority Interest | C24: =-B24/1000 -> 0 | F24: =E24-C24 -> 0 | I24: =H24-C24 -> 0
A25: PL_MI_CJE - NCI (CJE) | C25: =-B25/1000 -> 0 | F25: =E25-C25 -> 0 | I25: =H25-C25 -> 0
A26: ATT_OWN - Profit Or Loss Attributable To Owners Of The Company | B26: 12224730 | C26: =-B26/1000 -> -12224.73

Sheet SAP BFC REPORT
H2: 18277
H3: WFS DENMARK
H5: Denmark
B6: WFS CODE | D6: LABEL
B7: 7R0000 | D7: Total Revenue | H7: 200353
B8: 4R6000 | D8: Field Contribution excluding ROU rent cancellations | H8: 53331
B9: 4R4000 | D9: SG&A incl. Interco adjustments & elimination | H9: -17692
B10: 4R3000 | D10: Adjusted EBITDA excluding IFRS16 and Mgt fees/royalties | H10: 35639
B11: 5R0020 | D11: Other operational incomes/expenses
B12: 3R7000 | D12: EBITDA excl. management fees and royalties | H12: 35639
B13: 3R4000 | D13: Depreciation excl ROU & Amortization | H13: -1540
B14: 3R1100 | D14: EBIT excluding IFR16 and Management fees | H14: 34099
B15: 3R3000 | D15: Depreciation ROU&Concession | H15: -5018
B16: 3R8000 | D16: ROU Rental cancellations
B17: 3R1000 | D17: EBIT excl. management fees and royalties | H17: 29081
B18: 2R9000 | D18: Management fees and royalties | H18: -9263
B19: 2R0000 | D19: Operating Result | H19: 19818
B20: 2R0080 | D20: Share of profit/loss of associates
B21: 2R0050B | D21: Non Operating Income/ Expenses | H21: -309
B22: 2R6000 | D22: Interest expenses excluding ROU interests including Interco adjustments & elimination | H22: 7345
B23: 2R5000 | D23: Interest ROU and Concession | H23: -11089
B24: 7R0430 | D24: Exchange rate Gain / Loss | H24: -92
B25: 2R3000 | D25: PBT | H25: 15673
B26: 2R2000 | D26: Current Income Tax | H26: -3448
B27: 7R0630 | D27: Deferred income tax
B28: 2R0070 | D28: Minority interests in Profit or Loss
B29: 1R0000 | D29: Net Result | H29: 12225
B33: 1R0020 | D33: Adjusted EBITDA excluding all Service fees | H33: 35639
B35: CONTROL | D35: EBITDA | H35: 0
B38: SATS SUBTOT | D38: LABEL
B39: S-REVENUE | D39: Revenue | H39: 200353
D40: Operating expenses | H40: -171023
B41: S-EMPLOYMT | D41: Employement costs | H41: -126729
B42: S-DAP | D42: Depreciation and amortisation | H42: -6558
B43: S-LICENCE | D43: License fees
B44: S-UTILITY | D44: Company premise, utilities and maintenance | H44: -11470
B45: S-SUBCONTRCT | D45: Subcontracting Services | H45: -4713
B46: S-SUPPLY | D46: Cost of Raw Material and Supplies | H46: -2651
B47: S-OTHERCOST | D47: Other costs | H47: -18902
D48: Operating profit excl. Mgt fees/royalties | H48: 29330
...

Sheet TB BFC
A1: D_T | B1: D_U | C1: D_P | D1: D_E | E1: D_A | F1: D_M | G1: D_N | H1: D_F | I1: D_S | J1: D_C | K1: D_KH | L1: D_JOB | M1: D_CO | N1: D_CT | O1: D_OG | P1: D_RH | Q1: D_PP | R1: D_CU | S1: D_RE | T1: D_SU | U1: D_DEST | V1: D_MU | W1: D_PMU | X1: D_AIR | Y1: D_CRT | Z1: P_AMOUNT | AA1: P_COMMENT | AB1: LOCAL ACC
A2: ACTUAL | B2: 2025.12 | C2: 2025.12 | D2: 18277 | E2: 7R0020FD | F2: GL | G2: 0LOC0L | J2: DKK | L2: CAH | Z2: -60.10795 | AB2: =_xlfn.XLOOKUP(E2,[2]LOCAL!D:D,[2]LOCAL!H:H) -> 5220
A3: ACTUAL | B3: 2025.12 | C3: 2025.12 | D3: 18277 | E3: 7R0020FIS | F3: GL | G3: 0LOC0L | J3: DKK | L3: CAH | Z3: -2.2256 | AB3: =_xlfn.XLOOKUP(E3,[2]LOCAL!D:D,[2]LOCAL!H:H) -> 567020
A4: ACTUAL | B4: 2025.12 | C4: 2025.12 | D4: 18277 | E4: 7R0020HRS | F4: GL | G4: 0LOC0L | J4: DKK | L4: CAH | Z4: -27.75 | AB4: =_xlfn.XLOOKUP(E4,[2]LOCAL!D:D,[2]LOCAL!H:H) -> 567023
A5: ACTUAL | B5: 2025.12 | C5: 2025.12 | D5: 18277 | E5: 7R0020LES | F5: GL | G5: 0LOC0L | J5: DKK | L5: CAH | Z5: -6.99271 | AB5: =_xlfn.XLOOKUP(E5,[2]LOCAL!D:D,[2]LOCAL!H:H) -> 567025
A6: ACTUAL | B6: 2025.12 | C6: 2025.12 | D6: 18277 | E6: 7R0020OH | F6: GL | G6: 0LOC0L | J6: DKK | L6: CAH | Z6: -17.99442 | AB6: =_xlfn.XLOOKUP(E6,[2]LOCAL!D:D,[2]LOCAL!H:H) -> 567021
A7: ACTUAL | B7: 2025.12 | C7: 2025.12 | D7: 18277 | E7: 7R0020SDS | F7: GL | G7: 0LOC0L | J7: DKK | L7: CAH | Z7: -12.36942 | AB7: =_xlfn.XLOOKUP(E7,[2]LOCAL!D:D,[2]LOCAL!H:H) -> 567019
A8: ACTUAL | B8: 2025.12 | C8: 2025.12 | D8: 18277 | E8: 7R0020SSS | F8: GL | G8: 0LOC0L | J8: DKK | L8: CAH | Z8: -2.5 | AB8: =_xlfn.XLOOKUP(E8,[2]LOCAL!D:D,[2]LOCAL!H:H) -> 567024
A9: ACTUAL | B9: 2025.12 | C9: 2025.12 | D9: 18277 | E9: 7R0030EXS | F9: GL | G9: 0LOC0L | J9: DKK | L9: CAH | Z9: -327.20797 | AB9: =_xlfn.XLOOKUP(E9,[2]LOCAL!D:D,[2]LOCAL!H:H) -> 320026
A10: ACTUAL | B10: 2025.12 | C10: 2025.12 | D10: 18277 | E10: 7R0030FD | F10: GL | G10: 0LOC0L | J10: DKK | L10: CAH | Z10: -36.64829 | AB10: =_xlfn.XLOOKUP(E10,[2]LOCAL!D:D,[2]LOCAL!H:H) -> 320001
A11: ACTUAL | B11: 2025.12 | C11: 2025.12 | D11: 18277 | E11: 7R0030FIS | F11: GL | G11: 0LOC0L | J11: DKK | L11: CAH | Z11: -13.2608 | AB11: =_xlfn.XLOOKUP(E11,[2]LOCAL!D:D,[2]LOCAL!H:H) -> 320020
A12: ACTUAL | B12: 2025.12 | C12: 2025.12 | D12: 18277 | E12: 7R0030HRS | F12: GL | G12: 0LOC0L | J12: DKK | L12: CAH | Z12: -26.84925 | AB12: =_xlfn.XLOOKUP(E12,[2]LOCAL!D:D,[2]LOCAL!H:H) -> 320023
A13: ACTUAL | B13: 2025.12 | C13: 2025.12 | D13: 18277 | E13: 7R0030ITS | F13: GL | G13: 0LOC0L | J13: DKK | L13: CAH | Z13: -7.78692 | AB13: =_xlfn.XLOOKUP(E13,[2]LOCAL!D:D,[2]LOCAL!H:H) -> 320022
... A137: ACTUAL | B137: 2025.12 | C137: 2025.12 | D137: 18277 | E137: 9R3120 | F137: GL | G137: 0LOC0L | J137: DKK | L137: CAH | Z137: -92.78868 | AB137: =_xlfn.XLOOKUP(E137,[2]LOCAL!D:D,[2]LOCAL!H:H) -> 7630
A138: ACTUAL | B138: 2025.12 | C138: 2025.12 | D138: 18277 | E138: A190 | F138: F99 | G138: 0LOC0L | J138: DKK | Z138: 7087.9812 | AB138: =_xlfn.XLOOKUP(E138,[2]LOCAL!D:D,[2]LOCAL!H:H) -> 10060
A139: ACTUAL | B139: 2025.12 | C139: 2025.12 | D139: 18277 | E139: A1908 | F139: F99 | G139: 0LOC0L | J139: DKK | Z139: -7087.9812 | AB139: =_xlfn.XLOOKUP(E139,[2]LOCAL!D:D,[2]LOCAL!H:H) -> 10075
A140: ACTUAL | B140: 2025.12 | C140: 2025.12 | D140: 18277 | E140: A410 | F140: F99 | G140: 0LOC0L | J140: DKK | Z140: 2963.381 | AB140: =_xlfn.XLOOKUP(E140,[2]LOCAL!D:D,[2]LOCAL!H:H) -> 10400
A141: ACTUAL | B141: 2025.12 | C141: 2025.12 | D141: 18277 | E141: A4108 | F141: F99 | G141: 0LOC0L | J141: DKK | Z141: -466.90997 | AB141: =_xlfn.XLOOKUP(E141,[2]LOCAL!D:D,[2]LOCAL!H:H) -> 10430
A142: ACTUAL | B142: 2025.12 | C142: 2025.12 | D142: 18277 | E142: A415 | F142: F99 | G142: 0LOC0L | J142: DKK | Z142: 905.18808 | AB142: =_xlfn.XLOOKUP(E142,[2]LOCAL!D:D,[2]LOCAL!H:H) -> 13200
A143: ACTUAL | B143: 2025.12 | C143: 2025.12 | D143: 18277 | E143: A4158 | F143: F99 | G143: 0LOC0L | J143: DKK | Z143: -331.79016 | AB143: =_xlfn.XLOOKUP(E143,[2]LOCAL!D:D,[2]LOCAL!H:H) -> 13450
A144: ACTUAL | B144: 2025.12 | C144: 2025.12 | D144: 18277 | E144: A425 | F144: F99 | G144: 0LOC0L | J144: DKK | Z144: 9344.3438 | AB144: =_xlfn.XLOOKUP(E144,[2]LOCAL!D:D,[2]LOCAL!H:H) -> 11200
A145: ACTUAL | B145: 2025.12 | C145: 2025.12 | D145: 18277 | E145: A4258 | F145: F99 | G145: 0LOC0L | J145: DKK | Z145: -2818.7237 | AB145: =_xlfn.XLOOKUP(E145,[2]LOCAL!D:D,[2]LOCAL!H:H) -> 11450
A146: ACTUAL | B146: 2025.12 | C146: 2025.12 | D146: 18277 | E146: A491 | F146: F99 | G146: 0LOC0L | J146: DKK | Z146: 196667.14 | AB146: =_xlfn.XLOOKUP(E146,[2]LOCAL!D:D,[2]LOCAL!H:H) -> 13610
A147: ACTUAL | B147: 2025.12 | C147: 2025.12 | D147: 18277 | E147: A4918 | F147: F99 | G147: 0LOC0L | J147: DKK | Z147: -72404.509 | AB147: =_xlfn.XLOOKUP(E147,[2]LOCAL!D:D,[2]LOCAL!H:H) -> 13650
A148: ACTUAL | B148: 2025.12 | C148: 2025.12 | D148: 18277 | E148: A492 | F148: F99 | G148: 0LOC0L | J148: DKK | Z148: 15265.695 | AB148: =_xlfn.XLOOKUP(E148,[2]LOCAL!D:D,[2]LOCAL!H:H) -> 13691
A149: ACTUAL | B149: 2025.12 | C149: 2025.12 | D149: 18277 | E149: A4928 | F149: F99 | G149: 0LOC0L | J149: DKK | Z149: -4697.4852 | AB149: =_xlfn.XLOOKUP(E149,[2]LOCAL!D:D,[2]LOCAL!H:H) -> 13694
... A172: ACTUAL | B172: 2025.12 | C172: 2025.12 | D172: 18277 | E172: P816 | F172: F99 | G172: 0LOC0L | J172: DKK | Z172: 1027.9636 | AB172: =_xlfn.XLOOKUP(E172,[2]LOCAL!D:D,[2]LOCAL!H:H) -> 24271

Sheet ERP TO SAP BFC Mapping

Sheet OS TB
A1: Entities | B1: Scenario | C1: Time | D1: Cons | E1: View | F1: Local COA | G1: SAP COA | H1: SATS_COA | I1: Flow | J1: Origin | K1: IC | L1: LOB | M1: Function | N1: Aviation | O1: Audit | P1: Analysis | Q1: UD6# | R1: UD7# | S1: UD8# | T1: Source Id | U1: Amount
A2: 2708 | F2: 10065 - Additions | G2: A190 | H2: 1521300 | K2: None | T2: 2708_TB | U2: 7087981 | V2: =LEFT(H2,3) -> 152
A3: 2708 | F3: 10075 - Depreciation beginning of the year | G3: A1908 | H3: 1525300 | K3: None | T3: 2708_TB | U3: -7087981 | V3: =LEFT(H3,3) -> 152
A4: 2708 | F4: 1100 - Revenue Cargo DK Import | G4: 9R0010 | H4: 410010102 | K4: None | L4: 3A01 | M4: FLDS | N4: 1 | T4: 2708_TB | U4: -619905 | V4: =LEFT(H4,3) -> 410
A5: 2708 | F5: 1101 - Revenue Cargo DK Export | G5: 9R0011 | H5: 410010104 | K5: None | L5: 3A01 | M5: FLDS | N5: 1 | T5: 2708_TB | U5: 0 | V5: =LEFT(H5,3) -> 410
A6: 2708 | F6: 1110 - Revenue Cargo EU (services) Im | G6: 9R0010 | H6: 410010102 | K6: None | L6: 3A01 | M6: FLDS | N6: 1 | T6: 2708_TB | U6: -34346 | V6: =LEFT(H6,3) -> 410
A7: 2708 | F7: 1111 - Revenue Cargo EU (service) Exp | G7: 9R0011 | H7: 410010104 | K7: None | L7: 3A01 | M7: FLDS | N7: 1 | T7: 2708_TB | U7: -480 | V7: =LEFT(H7,3) -> 410
A8: 2708 | F8: 1120 - Revenue Cargo outside EU (C) I | G8: 9R0010 | H8: 410010102 | K8: None | L8: 3A01 | M8: FLDS | N8: 1 | T8: 2708_TB | U8: -29466088 | V8: =LEFT(H8,3) -> 410
A9: 2708 | F9: 11200 - Costs beginning of the year | G9: A425 | H9: 1500140 | K9: None | T9: 2708_TB | U9: 6782312 | V9: =LEFT(H9,3) -> 150
A10: 2708 | F10: 1121 - Revenue Cargo outside EU (C) E | G10: 9R0011 | H10: 410010104 | K10: None | L10: 3A01 | M10: FLDS | N10: 1 | T10: 2708_TB | U10: -57102409 | V10: =LEFT(H10,3) -> 410
A11: 2708 | F11: 1122 - Revenue Cargo outside EU Export - GSA | G11: 9R0011 | H11: 410010104 | K11: None | L11: 3A01 | M11: FLDS | N11: 1 | T11: 2708_TB | U11: -1037173 | V11: =LEFT(H11,3) -> 410
A12: 2708 | F12: 1130 - Revenue X-ray (forwarders) | G12: 8R0012 | H12: 410030106 | K12: None | L12: 3A01 | M12: FLDS | N12: 1 | T12: 2708_TB | U12: -4664476 | V12: =LEFT(H12,3) -> 410
A13: 2708 | F13: 11300 - Additions | G13: A425 | H13: 1500140 | K13: None | T13: 2708_TB | U13: 3276401 | V13: =LEFT(H13,3) -> 150
A14: 2708 | F14: 1131 - Revenue X-ray (forwarders) EU (Service) | G14: 8R0012 | H14: 410030106 | K14: None | L14: 3A01 | M14: FLDS | N14: 1 | T14: 2708_TB | U14: -29535 | V14: =LEFT(H14,3) -> 410
A15: 2708 | F15: 1140 - Revenue X-ray (airlines) | G15: 8R0012 | H15: 410030106 | K15: None | L15: 3A01 | M15: FLDS | N15: 1 | T15: 2708_TB | U15: -952386 | V15: =LEFT(H15,3) -> 410
A16: 2708 | F16: 11400 - Disposals | G16: A425 | H16: 1500140 | K16: None | T16: 2708_TB | U16: -714369 | V16: =LEFT(H16,3) -> 150
A17: 2708 | F17: 1142 - Revenue X-ray (airlines) (outside EU) - GSA | G17: 8R0012 | H17: 410030106 | K17: None | L17: 3A01 | M17: FLDS | N17: 1 | T17: 2708_TB | U17: -2050 | V17: =LEFT(H17,3) -> 410
A18: 2708 | F18: 11450 - Depreciation beginning of the year | G18: A4258 | H18: 1505104 | K18: None | T18: 2708_TB | U18: -1912505 | V18: =LEFT(H18,3) -> 150
A19: 2708 | F19: 1150 - Revenue Trucking DK | G19: 8R0011 | H19: 410010114 | K19: None | L19: 3A01 | M19: FLDS | N19: 1 | T19: 2708_TB | U19: 0 | V19: =LEFT(H19,3) -> 410
A20: 2708 | F20: 11500 - Depreciation | G20: A4258 | H20: 1505104 | K20: None | T20: 2708_TB | U20: -1371693 | V20: =LEFT(H20,3) -> 150
A21: 2708 | F21: 11550 - Depreciation on disposals | G21: A4258 | H21: 1505104 | K21: None | T21: 2708_TB | U21: 465474 | V21: =LEFT(H21,3) -> 150
A22: 2708 | F22: 1160 - Revenue Trucking EU | G22: 8R0011 | H22: 410010114 | K22: None | L22: 3A01 | M22: FLDS | N22: 1 | T22: 2708_TB | U22: 0 | V22: =LEFT(H22,3) -> 410
A23: 2708 | F23: 1170 - Revenue Trucking outside EU | G23: 8R0011 | H23: 410010114 | K23: None | L23: 3A01 | M23: FLDS | N23: 1 | T23: 2708_TB | U23: 0 | V23: =LEFT(H23,3) -> 410
A24: 2708 | F24: 1180 - Revenue Ramphandling | G24: 8R0015 | H24: 410030104 | K24: None | L24: 3A01 | M24: FLDS | N24: 1 | T24: 2708_TB | U24: 0 | V24: =LEFT(H24,3) -> 410
A25: 2708 | F25: 1190 - Revenue Offlinehandling | G25: 8R0013 | H25: 410030103 | K25: None | L25: 3A01 | M25: FLDS | N25: 1 | T25: 2708_TB | U25: -181455 | V25: =LEFT(H25,3) -> 410
A26: 2708 | F26: 12200 - Costs beginning of the year | G26: A410 | H26: 1500200 | K26: None | T26: 2708_TB | U26: 2963381 | V26: =LEFT(H26,3) -> 150
A27: 2708 | F27: 12300 - Additions | G27: A410 | H27: 1500200 | K27: None | T27: 2708_TB | U27: 0 | V27: =LEFT(H27,3) -> 150
A28: 2708 | F28: 12450 - Depreciation beginning of the year | G28: A4108 | H28: 1505200 | K28: None | T28: 2708_TB | U28: -389700 | V28: =LEFT(H28,3) -> 150
A29: 2708 | F29: 12500 - Depreciation | G29: A4108 | H29: 1505200 | K29: None | T29: 2708_TB | U29: -77210 | V29: =LEFT(H29,3) -> 150
A30: 2708 | F30: 1300 - Revenue Rental | G30: 8R0017 | H30: 410080103 | K30: None | L30: 3A01 | M30: FLDS | N30: 1 | T30: 2708_TB | U30: -1254439 | V30: =LEFT(H30,3) -> 410
A31: 2708 | F31: 13200 - Cost beginning of the year | G31: A415 | H31: 1500130 | K31: None | T31: 2708_TB | U31: 807387 | V31: =LEFT(H31,3) -> 150
A32: 2708 | F32: 13300 - Additions | G32: A415 | H32: 1500130 | K32: None | T32: 2708_TB | U32: 463135 | V32: =LEFT(H32,3) -> 150
A33: 2708 | F33: 13400 - Disposals | G33: A415 | H33: 1500130 | K33: None | T33: 2708_TB | U33: -365334 | V33: =LEFT(H33,3) -> 150
A34: 2708 | F34: 13450 - Depreciation beginning of the year | G34: A4158 | H34: 1505103 | K34: None | T34: 2708_TB | U34: -544736 | V34: =LEFT(H34,3) -> 150
A35: 2708 | F35: 1349 - Revenue THC Import EU (service) | G35: 9R00121 | H35: 410010113 | K35: None | L35: 3A01 | M35: FLDS | N35: 1 | T35: 2708_TB | U35: -6711506 | V35: =LEFT(H35,3) -> 410
A36: 2708 | F36: 1350 - Revenue THC Import | G36: 9R00121 | H36: 410010113 | K36: None | L36: 3A01 | M36: FLDS | N36: 1 | T36: 2708_TB | U36: -37957106 | V36: =LEFT(H36,3) -> 410
A37: 2708 | F37: 13500 - Depreciation | G37: A4158 | H37: 1505103 | K37: None | T37: 2708_TB | U37: -152388 | V37: =LEFT(H37,3) -> 150
A38: 2708 | F38: 1351 - Revenue THC Export | G38: 9R00121 | H38: 410010113 | K38: None | L38: 3A01 | M38: FLDS | N38: 1 | T38: 2708_TB | U38: -35646571 | V38: =LEFT(H38,3) -> 410
A39: 2708 | F39: 1352 - Revenue THC Export EU (service) | G39: 9R00121 | H39: 410010113 | K39: None | L39: 3A01 | M39: FLDS | N39: 1 | T39: 2708_TB | U39: -853240 | V39: =LEFT(H39,3) -> 410
A40: 2708 | F40: 13550 - Depreciation on disposals | G40: A4158 | H40: 1505103 | K40: None | T40: 2708_TB | U40: 365334 | V40: =LEFT(H40,3) -> 150
...

Sheet ERP TO OS MAPPING
A1: Local COA | B1: OS Mapping
A2: 10065 - Additions | B2: 1521300
A3: 10075 - Depreciation beginning of the year | B3: 1525300
A4: 1100 - Revenue Cargo DK Import | B4: 410010102
A5: 1101 - Revenue Cargo DK Export | B5: 410010104
A6: 1110 - Revenue Cargo EU (services) Im | B6: 410010102
A7: 1111 - Revenue Cargo EU (service) Exp | B7: 410010104
A8: 1120 - Revenue Cargo outside EU (C) I | B8: 410010102
A9: 11200 - Costs beginning of the year | B9: 1500140
A10: 1121 - Revenue Cargo outside EU (C) E | B10: 410010104
A11: 1122 - Revenue Cargo outside EU Export - GSA | B11: 410010104
A12: 1130 - Revenue X-ray (forwarders) | B12: 410030106
A13: 11300 - Additions | B13: 1500140
... A524: 9210 - Reg. tax prior years | B524: 607100101

Sheet OS to BFC L2 Mapping
A1: WFS ACCNT | B1: OS Level 2 Mapping
A3: 9R0010 | B3: 4100000 - Revenue
A4: 9R0011 | B4: 4100000 - Revenue
A5: 9R00121 | B5: 4100000 - Revenue
A6: 9R00122 | B6: 4100000 - Revenue
A7: 9R0013 | B7: 4100000 - Revenue
A8: 9R0014 | B8: 4100000 - Revenue
A9: 8R0010
A10: 8R0011 | B10: 4100000 - Revenue
A11: 8R0012 | B11: 4100000 - Revenue
A12: 8R0013 | B12: 4100000 - Revenue
A13: 8R0014 | B13: 4100000 - Revenue
A14: 8R0015 | B14: 4100000 - Revenue
A15: 8R0016 | B15: 4100000 - Revenue
A16: 8R0017 | B16: 4100000 - Revenue
A17: 8R0018 | B17: 4100000 - Revenue
A18: 8R0019 | B18: 4100000 - Revenue
A19: 8R0020 | B19: 4100000 - Revenue
A20: 8R0021 | B20: 4100000 - Revenue
A21: 7R0000
A23: 9R1110FD | B23: 5020000 - Staff Costs
A24: 9R1120FD | B24: 5020000 - Staff Costs
A25: 9R1130FD | B25: 5020000 - Staff Costs
A26: 9R1135FD | B26: 5020000 - Staff Costs
A27: 9R1140FD | B27: 5020000 - Staff Costs
A28: 9R1150FD | B28: 5020000 - Staff Costs
A29: 9R1210FD | B29: 5020000 - Staff Costs
A30: 9R1220FD | B30: 5020000 - Staff Costs
A31: 9R1230FD | B31: 5020000 - Staff Costs
A32: 8R0130FD | B32: 5020000 - Staff Costs
A33: 8R0140FD | B33: 5020000 - Staff Costs
A34: 9R1510FD | B34: 5020000 - Staff Costs
A35: 9R1520FD | B35: 5020000 - Staff Costs
A36: 7R0010FD
A37: 7R0020FD | B37: 5020000 - Staff Costs
A38: 7R0030FD | B38: 5020000 - Staff Costs
A39: 9R1510FD | B39: 5060000 - Subcontracting services
A40: 9R1520FD | B40: 5060000 - Subcontracting services
A41: 8R0410FD | B41: 5060000 - Subcontracting services
A42: 8R0420FD | B42: 5060000 - Subcontracting services
...
